Workbook

Sheet README
B2: Yasir A. Malik — NJ/NYC Job Pipeline Dashboard
B3: Curated pipeline of audit, risk, and AI-governance roles in the NJ/NYC corridor
B5: HOW TO USE THIS WORKBOOK
B6: Dashboard | C6: KPI cards + top-10 leaderboard. Start here every Monday morning.
B7: Top Ranked Jobs | C7: Full ranked table with composite score, fit, salary, and apply links.
B8: By Company | C8: Cross-tab: roles per employer with min/median/max salary mid and avg fit.
B9: By Type | C9: Cross-tab on category (G-SIB, Pharma, Biotech, Consulting, Academic, …) plus chart.
B10: Tier Summary | C10: Counts and salary ranges per tier (1 = bullseye, 4 = adjunct). Includes chart.
B11: Action Plan | C11: Week-by-week application schedule for the next four weeks.
B13: Built 2026-05-22 · Yasir A. Malik · YasirAMalik@gmail.com

Sheet Dashboard
B2: JOB PIPELINE — DASHBOARD
B6: TOTAL ROLES | F6: ROLES ≥ $200K MID | J6: ROLES WITH FIT ≥ 9.0
B7: =COUNTA('Top Ranked Jobs'!D7:D55) | F7: =COUNTIF('Top Ranked Jobs'!K7:K55,">=200000") | J7: =COUNTIF('Top Ranked Jobs'!L7:L55,">=9")
B11: MEDIAN SALARY MID | F11: TOP COMPOSITE SCORE | J11: AVG FIT SCORE
B12: =MEDIAN('Top Ranked Jobs'!K7:K55) | F12: =MAX('Top Ranked Jobs'!M7:M55) | J12: =ROUND(AVERAGE('Top Ranked Jobs'!L7:L55),1)
B15: TOP 10 — BY COMPOSITE SCORE
B16: Rank | C16: Company | D16: Title | E16: Tier | F16: Sal Mid | G16: Fit | H16: Composite | I16: Apply
B17: 1 | C17: ='Top Ranked Jobs'!D7 | D17: ='Top Ranked Jobs'!E7 | E17: ='Top Ranked Jobs'!C7 | F17: ='Top Ranked Jobs'!K7 | G17: ='Top Ranked Jobs'!L7 | H17: ='Top Ranked Jobs'!M7 | I17: Apply ▸
B18: 2 | C18: ='Top Ranked Jobs'!D8 | D18: ='Top Ranked Jobs'!E8 | E18: ='Top Ranked Jobs'!C8 | F18: ='Top Ranked Jobs'!K8 | G18: ='Top Ranked Jobs'!L8 | H18: ='Top Ranked Jobs'!M8 | I18: Apply ▸
B19: 3 | C19: ='Top Ranked Jobs'!D9 | D19: ='Top Ranked Jobs'!E9 | E19: ='Top Ranked Jobs'!C9 | F19: ='Top Ranked Jobs'!K9 | G19: ='Top Ranked Jobs'!L9 | H19: ='Top Ranked Jobs'!M9 | I19: Apply ▸
B20: 4 | C20: ='Top Ranked Jobs'!D10 | D20: ='Top Ranked Jobs'!E10 | E20: ='Top Ranked Jobs'!C10 | F20: ='Top Ranked Jobs'!K10 | G20: ='Top Ranked Jobs'!L10 | H20: ='Top Ranked Jobs'!M10 | I20: Apply ▸
B21: 5 | C21: ='Top Ranked Jobs'!D11 | D21: ='Top Ranked Jobs'!E11 | E21: ='Top Ranked Jobs'!C11 | F21: ='Top Ranked Jobs'!K11 | G21: ='Top Ranked Jobs'!L11 | H21: ='Top Ranked Jobs'!M11 | I21: Apply ▸
B22: 6 | C22: ='Top Ranked Jobs'!D12 | D22: ='Top Ranked Jobs'!E12 | E22: ='Top Ranked Jobs'!C12 | F22: ='Top Ranked Jobs'!K12 | G22: ='Top Ranked Jobs'!L12 | H22: ='Top Ranked Jobs'!M12 | I22: Apply ▸
B23: 7 | C23: ='Top Ranked Jobs'!D13 | D23: ='Top Ranked Jobs'!E13 | E23: ='Top Ranked Jobs'!C13 | F23: ='Top Ranked Jobs'!K13 | G23: ='Top Ranked Jobs'!L13 | H23: ='Top Ranked Jobs'!M13 | I23: Apply ▸
B24: 8 | C24: ='Top Ranked Jobs'!D14 | D24: ='Top Ranked Jobs'!E14 | E24: ='Top Ranked Jobs'!C14 | F24: ='Top Ranked Jobs'!K14 | G24: ='Top Ranked Jobs'!L14 | H24: ='Top Ranked Jobs'!M14 | I24: Apply ▸
B25: 9 | C25: ='Top Ranked Jobs'!D15 | D25: ='Top Ranked Jobs'!E15 | E25: ='Top Ranked Jobs'!C15 | F25: ='Top Ranked Jobs'!K15 | G25: ='Top Ranked Jobs'!L15 | H25: ='Top Ranked Jobs'!M15 | I25: Apply ▸
B26: 10 | C26: ='Top Ranked Jobs'!D16 | D26: ='Top Ranked Jobs'!E16 | E26: ='Top Ranked Jobs'!C16 | F26: ='Top Ranked Jobs'!K16 | G26: ='Top Ranked Jobs'!L16 | H26: ='Top Ranked Jobs'!M16 | I26: Apply ▸

Sheet Top Ranked Jobs
B2: Top Ranked Jobs
B3: All 49 roles, sorted by tier then composite. Click Apply ▸ to open the live careers page.
B4: Composite = Sal Mid × Fit / 10. Conditional formatting highlights the strongest leads.
B6: Rank | C6: Tier | D6: Company | E6: Title | F6: Req# | G6: Type | H6: Location | I6: Sal Low | J6: Sal High | K6: Sal Mid | L6: Fit | M6: Composite | N6: Sal as posted | O6: Posted | P6: Apply | Q6: Why ranked here
B7: 1 | C7: 1 | D7: JPMorgan Chase | E7: Executive Director, AI/ML Audit | F7: — | G7: G-SIB Bank | H7: Jersey City, NJ / NYC | I7: 250000 | J7: 350000 | K7: =(I7+J7)/2 | L7: 9.5 | M7: =K7*L7/10 | N7: $250K–$350K | O7: May 2026 | P7: Apply ▸ | Q7: Boomerang to JPM where Yasir already led CCAR + RRP for $2.6T balance sheet. Title bump to ED is overdue and the AI audit lane is brand new.
B8: 2 | C8: 1 | D8: BNY | E8: Managing Director, AI Governance Audit | F8: — | G8: G-SIB Bank | H8: New York, NY | I8: 230000 | J8: 330000 | K8: =(I8+J8)/2 | L8: 9.2 | M8: =K8*L8/10 | N8: $230K–$330K | O8: May 2026 | P8: Apply ▸ | Q8: Custody bank tackling AI agent risk on settlement workflows. MD level, NYC commutable, and BNY is publicly hiring across AI risk teams.
B9: 3 | C9: 1 | D9: Bristol Myers Squibb | E9: Executive Director, Internal Audit | F9: — | G9: Corporate Pharma | H9: Princeton, NJ | I9: 220000 | J9: 310000 | K9: =(I9+J9)/2 | L9: 9.4 | M9: =K9*L9/10 | N9: $220K–$310K | O9: Apr 2026 | P9: Apply ▸ | Q9: Princeton commute, Big Pharma scale, ED title with global remit. Audit + AI controls increasingly central to BMS post-Celgene integration.
B10: 4 | C10: 1 | D10: Morgan Stanley | E10: Executive Director, Technology & AI Audit | F10: — | G10: G-SIB Bank | H10: New York, NY | I10: 220000 | J10: 320000 | K10: =(I10+J10)/2 | L10: 9 | M10: =K10*L10/10 | N10: $220K–$320K | O10: May 2026 | P10: Apply ▸ | Q10: Wealth + IBD AI assurance scope. Yasir's SR 11-7 + GenAI controls framework experience plugs directly into MS's expanding tech audit footprint.
B11: 5 | C11: 1 | D11: Goldman Sachs | E11: VP, AI Governance & Model Risk Audit | F11: — | G11: G-SIB Bank | H11: New York, NY | I11: 220000 | J11: 310000 | K11: =(I11+J11)/2 | L11: 9 | M11: =K11*L11/10 | N11: $220K–$310K | O11: Apr 2026 | P11: Apply ▸ | Q11: GS Internal Audit has the most mature AI assurance program on the Street. VP at GS pays at JPM ED equivalent.
B12: 6 | C12: 1 | D12: Prudential Financial | E12: VP, Internal Audit — AI & Model Risk | F12: — | G12: Corporate | H12: Newark, NJ | I12: 200000 | J12: 290000 | K12: =(I12+J12)/2 | L12: 9.6 | M12: =K12*L12/10 | N12: $200K–$290K | O12: May 2026 | P12: Apply ▸ | Q12: Newark HQ, exact AI+model-risk audit mandate, VP/Director scope mirrors Yasir's Citi role. Highest geographic and domain fit on the board.
B13: 7 | C13: 1 | D13: Johnson & Johnson | E13: Senior Director, Internal Audit — AI & Digital | F13: — | G13: Corporate Pharma | H13: New Brunswick, NJ | I13: 200000 | J13: 280000 | K13: =(I13+J13)/2 | L13: 9.2 | M13: =K13*L13/10 | N13: $200K–$280K | O13: Apr 2026 | P13: Apply ▸ | Q13: Newark train to New Brunswick, J&J's Tech & Data audit team is the strongest in NJ pharma. Sr Director maps to MD-equivalent.
B14: 8 | C14: 1 | D14: Citi | E14: Director, AI Audit (return engagement) | F14: — | G14: G-SIB Bank | H14: New York, NY | I14: 200000 | J14: 290000 | K14: =(I14+J14)/2 | L14: 9 | M14: =K14*L14/10 | N14: $200K–$290K | O14: May 2026 | P14: Apply ▸ | Q14: Boomerang. Citi consent-order audit work + AI governance fluency makes Yasir a known quantity. Keep warm — internal mobility is the cleanest re-entry.
B15: 9 | C15: 1 | D15: Merck | E15: Director, Internal Audit — Technology & AI | F15: — | G15: Corporate Pharma | H15: Rahway, NJ | I15: 185000 | J15: 260000 | K15: =(I15+J15)/2 | L15: 9.1 | M15: =K15*L15/10 | N15: $185K–$260K | O15: Apr 2026 | P15: Apply ▸ | Q15: Rahway HQ, 30 min from Newark. Merck has standing AI/ML audit team and is hiring continuously across IT and data audit.
B16: 10 | C16: 2 | D16: Wells Fargo | E16: SVP, AI Risk Oversight (3LOD audit) | F16: — | G16: G-SIB Bank | H16: New York, NY | I16: 190000 | J16: 260000 | K16: =(I16+J16)/2 | L16: 8.4 | M16: =K16*L16/10 | N16: $190K–$260K | O16: Apr 2026 | P16: Apply ▸ | Q16: WFC post-consent-order build-out continues. Yasir's Citi consent-order experience is a near-perfect signal.
B17: 11 | C17: 2 | D17: PwC | E17: Director, Risk Assurance — AI & Model Risk | F17: — | G17: Big 4 Consulting | H17: Florham Park, NJ | I17: 180000 | J17: 260000 | K17: =(I17+J17)/2 | L17: 8.3 | M17: =K17*L17/10 | N17: $180K–$260K | O17: Apr 2026 | P17: Apply ▸ | Q17: Florham Park is a 35-min commute. PwC AI Risk practice is hiring aggressively; Yasir's DBA research is a marketing asset for the practice.
B18: 12 | C18: 2 | D18: BioNTech US | E18: Senior Director, Internal Audit | F18: — | G18: Biotech | H18: Berkeley Heights, NJ | I18: 185000 | J18: 260000 | K18: =(I18+J18)/2 | L18: 8 | M18: =K18*L18/10 | N18: $185K–$260K | O18: Mar 2026 | P18: Apply ▸ | Q18: Building US internal audit from scratch — Yasir's program-build experience at Citi consent-order work is the differentiator.
... B55: 49 | C55: 4 | D55: Essex County College | E55: Adjunct Faculty — Business Management | F55: — | G55: Academic-Adjunct | H55: Newark, NJ | I55: 0 | J55: 0 | K55: =(I55+J55)/2 | L55: 5.5 | M55: =K55*L55/10 | N55: $1,100/credit | O55: Feb 2026 | P55: Apply ▸ | Q55: Walk-to-work adjunct in Newark. Stacks the teaching credential without commute cost.

Sheet By Company
B2: By Company
B5: Employer | C5: Roles | D5: Min Sal Mid | E5: Median Sal Mid | F5: Max Sal Mid | G5: Avg Fit
B6: JPMorgan Chase | C6: =COUNTIF('Top Ranked Jobs'!D7:D55,"JPMorgan Chase") | D6: {=MIN(IF('Top Ranked Jobs'!D7:D55="JPMorgan Chase",'Top Ranked Jobs'!K7:K55))} | E6: {=MEDIAN(IF('Top Ranked Jobs'!D7:D55="JPMorgan Chase",'Top Ranked Jobs'!K7:K55))} | F6: {=MAX(IF('Top Ranked Jobs'!D7:D55="JPMorgan Chase",'Top Ranked Jobs'!K7:K55))} | G6: =ROUND(AVERAGEIF('Top Ranked Jobs'!D7:D55,"JPMorgan Chase",'Top Ranked Jobs'!L7:L55),1)
B7: BNY | C7: =COUNTIF('Top Ranked Jobs'!D7:D55,"BNY") | D7: {=MIN(IF('Top Ranked Jobs'!D7:D55="BNY",'Top Ranked Jobs'!K7:K55))} | E7: {=MEDIAN(IF('Top Ranked Jobs'!D7:D55="BNY",'Top Ranked Jobs'!K7:K55))} | F7: {=MAX(IF('Top Ranked Jobs'!D7:D55="BNY",'Top Ranked Jobs'!K7:K55))} | G7: =ROUND(AVERAGEIF('Top Ranked Jobs'!D7:D55,"BNY",'Top Ranked Jobs'!L7:L55),1)
B8: Bristol Myers Squibb | C8: =COUNTIF('Top Ranked Jobs'!D7:D55,"Bristol Myers Squibb") | D8: {=MIN(IF('Top Ranked Jobs'!D7:D55="Bristol Myers Squibb",'Top Ranked Jobs'!K7:K55))} | E8: {=MEDIAN(IF('Top Ranked Jobs'!D7:D55="Bristol Myers Squibb",'Top Ranked Jobs'!K7:K55))} | F8: {=MAX(IF('Top Ranked Jobs'!D7:D55="Bristol Myers Squibb",'Top Ranked Jobs'!K7:K55))} | G8: =ROUND(AVERAGEIF('Top Ranked Jobs'!D7:D55,"Bristol Myers Squibb",'Top Ranked Jobs'!L7:L55),1)
B9: Morgan Stanley | C9: =COUNTIF('Top Ranked Jobs'!D7:D55,"Morgan Stanley") | D9: {=MIN(IF('Top Ranked Jobs'!D7:D55="Morgan Stanley",'Top Ranked Jobs'!K7:K55))} | E9: {=MEDIAN(IF('Top Ranked Jobs'!D7:D55="Morgan Stanley",'Top Ranked Jobs'!K7:K55))} | F9: {=MAX(IF('Top Ranked Jobs'!D7:D55="Morgan Stanley",'Top Ranked Jobs'!K7:K55))} | G9: =ROUND(AVERAGEIF('Top Ranked Jobs'!D7:D55,"Morgan Stanley",'Top Ranked Jobs'!L7:L55),1)
B10: Goldman Sachs | C10: =COUNTIF('Top Ranked Jobs'!D7:D55,"Goldman Sachs") | D10: {=MIN(IF('Top Ranked Jobs'!D7:D55="Goldman Sachs",'Top Ranked Jobs'!K7:K55))} | E10: {=MEDIAN(IF('Top Ranked Jobs'!D7:D55="Goldman Sachs",'Top Ranked Jobs'!K7:K55))} | F10: {=MAX(IF('Top Ranked Jobs'!D7:D55="Goldman Sachs",'Top Ranked Jobs'!K7:K55))} | G10: =ROUND(AVERAGEIF('Top Ranked Jobs'!D7:D55,"Goldman Sachs",'Top Ranked Jobs'!L7:L55),1)
B11: Prudential Financial | C11: =COUNTIF('Top Ranked Jobs'!D7:D55,"Prudential Financial") | D11: {=MIN(IF('Top Ranked Jobs'!D7:D55="Prudential Financial",'Top Ranked Jobs'!K7:K55))} | E11: {=MEDIAN(IF('Top Ranked Jobs'!D7:D55="Prudential Financial",'Top Ranked Jobs'!K7:K55))} | F11: {=MAX(IF('Top Ranked Jobs'!D7:D55="Prudential Financial",'Top Ranked Jobs'!K7:K55))} | G11: =ROUND(AVERAGEIF('Top Ranked Jobs'!D7:D55,"Prudential Financial",'Top Ranked Jobs'!L7:L55),1)
B12: Johnson & Johnson | C12: =COUNTIF('Top Ranked Jobs'!D7:D55,"Johnson & Johnson") | D12: {=MIN(IF('Top Ranked Jobs'!D7:D55="Johnson & Johnson",'Top Ranked Jobs'!K7:K55))} | E12: {=MEDIAN(IF('Top Ranked Jobs'!D7:D55="Johnson & Johnson",'Top Ranked Jobs'!K7:K55))} | F12: {=MAX(IF('Top Ranked Jobs'!D7:D55="Johnson & Johnson",'Top Ranked Jobs'!K7:K55))} | G12: =ROUND(AVERAGEIF('Top Ranked Jobs'!D7:D55,"Johnson & Johnson",'Top Ranked Jobs'!L7:L55),1)
B13: Citi | C13: =COUNTIF('Top Ranked Jobs'!D7:D55,"Citi") | D13: {=MIN(IF('Top Ranked Jobs'!D7:D55="Citi",'Top Ranked Jobs'!K7:K55))} | E13: {=MEDIAN(IF('Top Ranked Jobs'!D7:D55="Citi",'Top Ranked Jobs'!K7:K55))} | F13: {=MAX(IF('Top Ranked Jobs'!D7:D55="Citi",'Top Ranked Jobs'!K7:K55))} | G13: =ROUND(AVERAGEIF('Top Ranked Jobs'!D7:D55,"Citi",'Top Ranked Jobs'!L7:L55),1)
B14: Merck | C14: =COUNTIF('Top Ranked Jobs'!D7:D55,"Merck") | D14: {=MIN(IF('Top Ranked Jobs'!D7:D55="Merck",'Top Ranked Jobs'!K7:K55))} | E14: {=MEDIAN(IF('Top Ranked Jobs'!D7:D55="Merck",'Top Ranked Jobs'!K7:K55))} | F14: {=MAX(IF('Top Ranked Jobs'!D7:D55="Merck",'Top Ranked Jobs'!K7:K55))} | G14: =ROUND(AVERAGEIF('Top Ranked Jobs'!D7:D55,"Merck",'Top Ranked Jobs'!L7:L55),1)
B15: Wells Fargo | C15: =COUNTIF('Top Ranked Jobs'!D7:D55,"Wells Fargo") | D15: {=MIN(IF('Top Ranked Jobs'!D7:D55="Wells Fargo",'Top Ranked Jobs'!K7:K55))} | E15: {=MEDIAN(IF('Top Ranked Jobs'!D7:D55="Wells Fargo",'Top Ranked Jobs'!K7:K55))} | F15: {=MAX(IF('Top Ranked Jobs'!D7:D55="Wells Fargo",'Top Ranked Jobs'!K7:K55))} | G15: =ROUND(AVERAGEIF('Top Ranked Jobs'!D7:D55,"Wells Fargo",'Top Ranked Jobs'!L7:L55),1)
B16: PwC | C16: =COUNTIF('Top Ranked Jobs'!D7:D55,"PwC") | D16: {=MIN(IF('Top Ranked Jobs'!D7:D55="PwC",'Top Ranked Jobs'!K7:K55))} | E16: {=MEDIAN(IF('Top Ranked Jobs'!D7:D55="PwC",'Top Ranked Jobs'!K7:K55))} | F16: {=MAX(IF('Top Ranked Jobs'!D7:D55="PwC",'Top Ranked Jobs'!K7:K55))} | G16: =ROUND(AVERAGEIF('Top Ranked Jobs'!D7:D55,"PwC",'Top Ranked Jobs'!L7:L55),1)
B17: BioNTech US | C17: =COUNTIF('Top Ranked Jobs'!D7:D55,"BioNTech US") | D17: {=MIN(IF('Top Ranked Jobs'!D7:D55="BioNTech US",'Top Ranked Jobs'!K7:K55))} | E17: {=MEDIAN(IF('Top Ranked Jobs'!D7:D55="BioNTech US",'Top Ranked Jobs'!K7:K55))} | F17: {=MAX(IF('Top Ranked Jobs'!D7:D55="BioNTech US",'Top Ranked Jobs'!K7:K55))} | G17: =ROUND(AVERAGEIF('Top Ranked Jobs'!D7:D55,"BioNTech US",'Top Ranked Jobs'!L7:L55),1)
B18: Insmed | C18: =COUNTIF('Top Ranked Jobs'!D7:D55,"Insmed") | D18: {=MIN(IF('Top Ranked Jobs'!D7:D55="Insmed",'Top Ranked Jobs'!K7:K55))} | E18: {=MEDIAN(IF('Top Ranked Jobs'!D7:D55="Insmed",'Top Ranked Jobs'!K7:K55))} | F18: {=MAX(IF('Top Ranked Jobs'!D7:D55="Insmed",'Top Ranked Jobs'!K7:K55))} | G18: =ROUND(AVERAGEIF('Top Ranked Jobs'!D7:D55,"Insmed",'Top Ranked Jobs'!L7:L55),1)
B19: ADP | C19: =COUNTIF('Top Ranked Jobs'!D7:D55,"ADP") | D19: {=MIN(IF('Top Ranked Jobs'!D7:D55="ADP",'Top Ranked Jobs'!K7:K55))} | E19: {=MEDIAN(IF('Top Ranked Jobs'!D7:D55="ADP",'Top Ranked Jobs'!K7:K55))} | F19: {=MAX(IF('Top Ranked Jobs'!D7:D55="ADP",'Top Ranked Jobs'!K7:K55))} | G19: =ROUND(AVERAGEIF('Top Ranked Jobs'!D7:D55,"ADP",'Top Ranked Jobs'!L7:L55),1)
B20: BD (Becton Dickinson) | C20: =COUNTIF('Top Ranked Jobs'!D7:D55,"BD (Becton Dickinson)") | D20: {=MIN(IF('Top Ranked Jobs'!D7:D55="BD (Becton Dickinson)",'Top Ranked Jobs'!K7:K55))} | E20: {=MEDIAN(IF('Top Ranked Jobs'!D7:D55="BD (Becton Dickinson)",'Top Ranked Jobs'!K7:K55))} | F20: {=MAX(IF('Top Ranked Jobs'!D7:D55="BD (Becton Dickinson)",'Top Ranked Jobs'!K7:K55))} | G20: =ROUND(AVERAGEIF('Top Ranked Jobs'!D7:D55,"BD (Becton Dickinson)",'Top Ranked Jobs'!L7:L55),1)
B21: Barclays | C21: =COUNTIF('Top Ranked Jobs'!D7:D55,"Barclays") | D21: {=MIN(IF('Top Ranked Jobs'!D7:D55="Barclays",'Top Ranked Jobs'!K7:K55))} | E21: {=MEDIAN(IF('Top Ranked Jobs'!D7:D55="Barclays",'Top Ranked Jobs'!K7:K55))} | F21: {=MAX(IF('Top Ranked Jobs'!D7:D55="Barclays",'Top Ranked Jobs'!K7:K55))} | G21: =ROUND(AVERAGEIF('Top Ranked Jobs'!D7:D55,"Barclays",'Top Ranked Jobs'!L7:L55),1)
B22: RSM US | C22: =COUNTIF('Top Ranked Jobs'!D7:D55,"RSM US") | D22: {=MIN(IF('Top Ranked Jobs'!D7:D55="RSM US",'Top Ranked Jobs'!K7:K55))} | E22: {=MEDIAN(IF('Top Ranked Jobs'!D7:D55="RSM US",'Top Ranked Jobs'!K7:K55))} | F22: {=MAX(IF('Top Ranked Jobs'!D7:D55="RSM US",'Top Ranked Jobs'!K7:K55))} | G22: =ROUND(AVERAGEIF('Top Ranked Jobs'!D7:D55,"RSM US",'Top Ranked Jobs'!L7:L55),1)
B23: SMBC | C23: =COUNTIF('Top Ranked Jobs'!D7:D55,"SMBC") | D23: {=MIN(IF('Top Ranked Jobs'!D7:D55="SMBC",'Top Ranked Jobs'!K7:K55))} | E23: {=MEDIAN(IF('Top Ranked Jobs'!D7:D55="SMBC",'Top Ranked Jobs'!K7:K55))} | F23: {=MAX(IF('Top Ranked Jobs'!D7:D55="SMBC",'Top Ranked Jobs'!K7:K55))} | G23: =ROUND(AVERAGEIF('Top Ranked Jobs'!D7:D55,"SMBC",'Top Ranked Jobs'!L7:L55),1)
B24: Bank of America | C24: =COUNTIF('Top Ranked Jobs'!D7:D55,"Bank of America") | D24: {=MIN(IF('Top Ranked Jobs'!D7:D55="Bank of America",'Top Ranked Jobs'!K7:K55))} | E24: {=MEDIAN(IF('Top Ranked Jobs'!D7:D55="Bank of America",'Top Ranked Jobs'!K7:K55))} | F24: {=MAX(IF('Top Ranked Jobs'!D7:D55="Bank of America",'Top Ranked Jobs'!K7:K55))} | G24: =ROUND(AVERAGEIF('Top Ranked Jobs'!D7:D55,"Bank of America",'Top Ranked Jobs'!L7:L55),1)
B25: Otsuka America Pharmaceutical | C25: =COUNTIF('Top Ranked Jobs'!D7:D55,"Otsuka America Pharmaceutical") | D25: {=MIN(IF('Top Ranked Jobs'!D7:D55="Otsuka America Pharmaceutical",'Top Ranked Jobs'!K7:K55))} | E25: {=MEDIAN(IF('Top Ranked Jobs'!D7:D55="Otsuka America Pharmaceutical",'Top Ranked Jobs'!K7:K55))} | F25: {=MAX(IF('Top Ranked Jobs'!D7:D55="Otsuka America Pharmaceutical",'Top Ranked Jobs'!K7:K55))} | G25: =ROUND(AVERAGEIF('Top Ranked Jobs'!D7:D55,"Otsuka America Pharmaceutical",'Top Ranked Jobs'!L7:L55),1)
B26: Panasonic North America | C26: =COUNTIF('Top Ranked Jobs'!D7:D55,"Panasonic North America") | D26: {=MIN(IF('Top Ranked Jobs'!D7:D55="Panasonic North America",'Top Ranked Jobs'!K7:K55))} | E26: {=MEDIAN(IF('Top Ranked Jobs'!D7:D55="Panasonic North America",'Top Ranked Jobs'!K7:K55))} | F26: {=MAX(IF('Top Ranked Jobs'!D7:D55="Panasonic North America",'Top Ranked Jobs'!K7:K55))} | G26: =ROUND(AVERAGEIF('Top Ranked Jobs'!D7:D55,"Panasonic North America",'Top Ranked Jobs'!L7:L55),1)
B27: RBC City National | C27: =COUNTIF('Top Ranked Jobs'!D7:D55,"RBC City National") | D27: {=MIN(IF('Top Ranked Jobs'!D7:D55="RBC City National",'Top Ranked Jobs'!K7:K55))} | E27: {=MEDIAN(IF('Top Ranked Jobs'!D7:D55="RBC City National",'Top Ranked Jobs'!K7:K55))} | F27: {=MAX(IF('Top Ranked Jobs'!D7:D55="RBC City National",'Top Ranked Jobs'!K7:K55))} | G27: =ROUND(AVERAGEIF('Top Ranked Jobs'!D7:D55,"RBC City National",'Top Ranked Jobs'!L7:L55),1)
B28: Embecta | C28: =COUNTIF('Top Ranked Jobs'!D7:D55,"Embecta") | D28: {=MIN(IF('Top Ranked Jobs'!D7:D55="Embecta",'Top Ranked Jobs'!K7:K55))} | E28: {=MEDIAN(IF('Top Ranked Jobs'!D7:D55="Embecta",'Top Ranked Jobs'!K7:K55))} | F28: {=MAX(IF('Top Ranked Jobs'!D7:D55="Embecta",'Top Ranked Jobs'!K7:K55))} | G28: =ROUND(AVERAGEIF('Top Ranked Jobs'!D7:D55,"Embecta",'Top Ranked Jobs'!L7:L55),1)
B29: Legend Biotech | C29: =COUNTIF('Top Ranked Jobs'!D7:D55,"Legend Biotech") | D29: {=MIN(IF('Top Ranked Jobs'!D7:D55="Legend Biotech",'Top Ranked Jobs'!K7:K55))} | E29: {=MEDIAN(IF('Top Ranked Jobs'!D7:D55="Legend Biotech",'Top Ranked Jobs'!K7:K55))} | F29: {=MAX(IF('Top Ranked Jobs'!D7:D55="Legend Biotech",'Top Ranked Jobs'!K7:K55))} | G29: =ROUND(AVERAGEIF('Top Ranked Jobs'!D7:D55,"Legend Biotech",'Top Ranked Jobs'!L7:L55),1)
B30: TD Bank | C30: =COUNTIF('Top Ranked Jobs'!D7:D55,"TD Bank") | D30: {=MIN(IF('Top Ranked Jobs'!D7:D55="TD Bank",'Top Ranked Jobs'!K7:K55))} | E30: {=MEDIAN(IF('Top Ranked Jobs'!D7:D55="TD Bank",'Top Ranked Jobs'!K7:K55))} | F30: {=MAX(IF('Top Ranked Jobs'!D7:D55="TD Bank",'Top Ranked Jobs'!K7:K55))} | G30: =ROUND(AVERAGEIF('Top Ranked Jobs'!D7:D55,"TD Bank",'Top Ranked Jobs'!L7:L55),1)
B31: State Street | C31: =COUNTIF('Top Ranked Jobs'!D7:D55,"State Street") | D31: {=MIN(IF('Top Ranked Jobs'!D7:D55="State Street",'Top Ranked Jobs'!K7:K55))} | E31: {=MEDIAN(IF('Top Ranked Jobs'!D7:D55="State Street",'Top Ranked Jobs'!K7:K55))} | F31: {=MAX(IF('Top Ranked Jobs'!D7:D55="State Street",'Top Ranked Jobs'!K7:K55))} | G31: =ROUND(AVERAGEIF('Top Ranked Jobs'!D7:D55,"State Street",'Top Ranked Jobs'!L7:L55),1)
B32: NRG Energy | C32: =COUNTIF('Top Ranked Jobs'!D7:D55,"NRG Energy") | D32: {=MIN(IF('Top Ranked Jobs'!D7:D55="NRG Energy",'Top Ranked Jobs'!K7:K55))} | E32: {=MEDIAN(IF('Top Ranked Jobs'!D7:D55="NRG Energy",'Top Ranked Jobs'!K7:K55))} | F32: {=MAX(IF('Top Ranked Jobs'!D7:D55="NRG Energy",'Top Ranked Jobs'!K7:K55))} | G32: =ROUND(AVERAGEIF('Top Ranked Jobs'!D7:D55,"NRG Energy",'Top Ranked Jobs'!L7:L55),1)
B33: Avis Budget Group | C33: =COUNTIF('Top Ranked Jobs'!D7:D55,"Avis Budget Group") | D33: {=MIN(IF('Top Ranked Jobs'!D7:D55="Avis Budget Group",'Top Ranked Jobs'!K7:K55))} | E33: {=MEDIAN(IF('Top Ranked Jobs'!D7:D55="Avis Budget Group",'Top Ranked Jobs'!K7:K55))} | F33: {=MAX(IF('Top Ranked Jobs'!D7:D55="Avis Budget Group",'Top Ranked Jobs'!K7:K55))} | G33: =ROUND(AVERAGEIF('Top Ranked Jobs'!D7:D55,"Avis Budget Group",'Top Ranked Jobs'!L7:L55),1)
B34: NJIT | C34: =COUNTIF('Top Ranked Jobs'!D7:D55,"NJIT") | D34: {=MIN(IF('Top Ranked Jobs'!D7:D55="NJIT",'Top Ranked Jobs'!K7:K55))} | E34: {=MEDIAN(IF('Top Ranked Jobs'!D7:D55="NJIT",'Top Ranked Jobs'!K7:K55))} | F34: {=MAX(IF('Top Ranked Jobs'!D7:D55="NJIT",'Top Ranked Jobs'!K7:K55))} | G34: =ROUND(AVERAGEIF('Top Ranked Jobs'!D7:D55,"NJIT",'Top Ranked Jobs'!L7:L55),1)
B35: Princeton University | C35: =COUNTIF('Top Ranked Jobs'!D7:D55,"Princeton University") | D35: {=MIN(IF('Top Ranked Jobs'!D7:D55="Princeton University",'Top Ranked Jobs'!K7:K55))} | E35: {=MEDIAN(IF('Top Ranked Jobs'!D7:D55="Princeton University",'Top Ranked Jobs'!K7:K55))} | F35: {=MAX(IF('Top Ranked Jobs'!D7:D55="Princeton University",'Top Ranked Jobs'!K7:K55))} | G35: =ROUND(AVERAGEIF('Top Ranked Jobs'!D7:D55,"Princeton University",'Top Ranked Jobs'!L7:L55),1)
B36: Crowe LLP | C36: =COUNTIF('Top Ranked Jobs'!D7:D55,"Crowe LLP") | D36: {=MIN(IF('Top Ranked Jobs'!D7:D55="Crowe LLP",'Top Ranked Jobs'!K7:K55))} | E36: {=MEDIAN(IF('Top Ranked Jobs'!D7:D55="Crowe LLP",'Top Ranked Jobs'!K7:K55))} | F36: {=MAX(IF('Top Ranked Jobs'!D7:D55="Crowe LLP",'Top Ranked Jobs'!K7:K55))} | G36: =ROUND(AVERAGEIF('Top Ranked Jobs'!D7:D55,"Crowe LLP",'Top Ranked Jobs'!L7:L55),1)
B37: SOLV Energy | C37: =COUNTIF('Top Ranked Jobs'!D7:D55,"SOLV Energy") | D37: {=MIN(IF('Top Ranked Jobs'!D7:D55="SOLV Energy",'Top Ranked Jobs'!K7:K55))} | E37: {=MEDIAN(IF('Top Ranked Jobs'!D7:D55="SOLV Energy",'Top Ranked Jobs'!K7:K55))} | F37: {=MAX(IF('Top Ranked Jobs'!D7:D55="SOLV Energy",'Top Ranked Jobs'!K7:K55))} | G37: =ROUND(AVERAGEIF('Top Ranked Jobs'!D7:D55,"SOLV Energy",'Top Ranked Jobs'!L7:L55),1)
B38: Baker Tilly | C38: =COUNTIF('Top Ranked Jobs'!D7:D55,"Baker Tilly") | D38: {=MIN(IF('Top Ranked Jobs'!D7:D55="Baker Tilly",'Top Ranked Jobs'!K7:K55))} | E38: {=MEDIAN(IF('Top Ranked Jobs'!D7:D55="Baker Tilly",'Top Ranked Jobs'!K7:K55))} | F38: {=MAX(IF('Top Ranked Jobs'!D7:D55="Baker Tilly",'Top Ranked Jobs'!K7:K55))} | G38: =ROUND(AVERAGEIF('Top Ranked Jobs'!D7:D55,"Baker Tilly",'Top Ranked Jobs'!L7:L55),1)
B39: Seton Hall University | C39: =COUNTIF('Top Ranked Jobs'!D7:D55,"Seton Hall University") | D39: {=MIN(IF('Top Ranked Jobs'!D7:D55="Seton Hall University",'Top Ranked Jobs'!K7:K55))} | E39: {=MEDIAN(IF('Top Ranked Jobs'!D7:D55="Seton Hall University",'Top Ranked Jobs'!K7:K55))} | F39: {=MAX(IF('Top Ranked Jobs'!D7:D55="Seton Hall University",'Top Ranked Jobs'!K7:K55))} | G39: =ROUND(AVERAGEIF('Top Ranked Jobs'!D7:D55,"Seton Hall University",'Top Ranked Jobs'!L7:L55),1)
B40: Rutgers University | C40: =COUNTIF('Top Ranked Jobs'!D7:D55,"Rutgers University") | D40: {=MIN(IF('Top Ranked Jobs'!D7:D55="Rutgers University",'Top Ranked Jobs'!K7:K55))} | E40: {=MEDIAN(IF('Top Ranked Jobs'!D7:D55="Rutgers University",'Top Ranked Jobs'!K7:K55))} | F40: {=MAX(IF('Top Ranked Jobs'!D7:D55="Rutgers University",'Top Ranked Jobs'!K7:K55))} | G40: =ROUND(AVERAGEIF('Top Ranked Jobs'!D7:D55,"Rutgers University",'Top Ranked Jobs'!L7:L55),1)
B41: Kearny Bank | C41: =COUNTIF('Top Ranked Jobs'!D7:D55,"Kearny Bank") | D41: {=MIN(IF('Top Ranked Jobs'!D7:D55="Kearny Bank",'Top Ranked Jobs'!K7:K55))} | E41: {=MEDIAN(IF('Top Ranked Jobs'!D7:D55="Kearny Bank",'Top Ranked Jobs'!K7:K55))} | F41: {=MAX(IF('Top Ranked Jobs'!D7:D55="Kearny Bank",'Top Ranked Jobs'!K7:K55))} | G41: =ROUND(AVERAGEIF('Top Ranked Jobs'!D7:D55,"Kearny Bank",'Top Ranked Jobs'!L7:L55),1)
B42: Robert Half (Mgmt Resources) | C42: =COUNTIF('Top Ranked Jobs'!D7:D55,"Robert Half (Mgmt Resources)") | D42: {=MIN(IF('Top Ranked Jobs'!D7:D55="Robert Half (Mgmt Resources)",'Top Ranked Jobs'!K7:K55))} | E42: {=MEDIAN(IF('Top Ranked Jobs'!D7:D55="Robert Half (Mgmt Resources)",'Top Ranked Jobs'!K7:K55))} | F42: {=MAX(IF('Top Ranked Jobs'!D7:D55="Robert Half (Mgmt Resources)",'Top Ranked Jobs'!K7:K55))} | G42: =ROUND(AVERAGEIF('Top Ranked Jobs'!D7:D55,"Robert Half (Mgmt Resources)",'Top Ranked Jobs'!L7:L55),1)
B43: Stevens Institute of Technology | C43: =COUNTIF('Top Ranked Jobs'!D7:D55,"Stevens Institute of Technology") | D43: {=MIN(IF('Top Ranked Jobs'!D7:D55="Stevens Institute of Technology",'Top Ranked Jobs'!K7:K55))} | E43: {=MEDIAN(IF('Top Ranked Jobs'!D7:D55="Stevens Institute of Technology",'Top Ranked Jobs'!K7:K55))} | F43: {=MAX(IF('Top Ranked Jobs'!D7:D55="Stevens Institute of Technology",'Top Ranked Jobs'!K7:K55))} | G43: =ROUND(AVERAGEIF('Top Ranked Jobs'!D7:D55,"Stevens Institute of Technology",'Top Ranked Jobs'!L7:L55),1)
...

Sheet By Type
B2: By Type
B5: Category | C5: Roles | D5: Min Sal Mid | E5: Median Sal Mid | F5: Max Sal Mid | G5: Avg Fit
B6: G-SIB Bank | C6: =COUNTIF('Top Ranked Jobs'!G7:G55,"G-SIB Bank") | D6: {=MIN(IF('Top Ranked Jobs'!G7:G55="G-SIB Bank",'Top Ranked Jobs'!K7:K55))} | E6: {=MEDIAN(IF('Top Ranked Jobs'!G7:G55="G-SIB Bank",'Top Ranked Jobs'!K7:K55))} | F6: {=MAX(IF('Top Ranked Jobs'!G7:G55="G-SIB Bank",'Top Ranked Jobs'!K7:K55))} | G6: =ROUND(AVERAGEIF('Top Ranked Jobs'!G7:G55,"G-SIB Bank",'Top Ranked Jobs'!L7:L55),1)
B7: Corporate Pharma | C7: =COUNTIF('Top Ranked Jobs'!G7:G55,"Corporate Pharma") | D7: {=MIN(IF('Top Ranked Jobs'!G7:G55="Corporate Pharma",'Top Ranked Jobs'!K7:K55))} | E7: {=MEDIAN(IF('Top Ranked Jobs'!G7:G55="Corporate Pharma",'Top Ranked Jobs'!K7:K55))} | F7: {=MAX(IF('Top Ranked Jobs'!G7:G55="Corporate Pharma",'Top Ranked Jobs'!K7:K55))} | G7: =ROUND(AVERAGEIF('Top Ranked Jobs'!G7:G55,"Corporate Pharma",'Top Ranked Jobs'!L7:L55),1)
B8: Corporate | C8: =COUNTIF('Top Ranked Jobs'!G7:G55,"Corporate") | D8: {=MIN(IF('Top Ranked Jobs'!G7:G55="Corporate",'Top Ranked Jobs'!K7:K55))} | E8: {=MEDIAN(IF('Top Ranked Jobs'!G7:G55="Corporate",'Top Ranked Jobs'!K7:K55))} | F8: {=MAX(IF('Top Ranked Jobs'!G7:G55="Corporate",'Top Ranked Jobs'!K7:K55))} | G8: =ROUND(AVERAGEIF('Top Ranked Jobs'!G7:G55,"Corporate",'Top Ranked Jobs'!L7:L55),1)
B9: Big 4 Consulting | C9: =COUNTIF('Top Ranked Jobs'!G7:G55,"Big 4 Consulting") | D9: {=MIN(IF('Top Ranked Jobs'!G7:G55="Big 4 Consulting",'Top Ranked Jobs'!K7:K55))} | E9: {=MEDIAN(IF('Top Ranked Jobs'!G7:G55="Big 4 Consulting",'Top Ranked Jobs'!K7:K55))} | F9: {=MAX(IF('Top Ranked Jobs'!G7:G55="Big 4 Consulting",'Top Ranked Jobs'!K7:K55))} | G9: =ROUND(AVERAGEIF('Top Ranked Jobs'!G7:G55,"Big 4 Consulting",'Top Ranked Jobs'!L7:L55),1)
B10: Biotech | C10: =COUNTIF('Top Ranked Jobs'!G7:G55,"Biotech") | D10: {=MIN(IF('Top Ranked Jobs'!G7:G55="Biotech",'Top Ranked Jobs'!K7:K55))} | E10: {=MEDIAN(IF('Top Ranked Jobs'!G7:G55="Biotech",'Top Ranked Jobs'!K7:K55))} | F10: {=MAX(IF('Top Ranked Jobs'!G7:G55="Biotech",'Top Ranked Jobs'!K7:K55))} | G10: =ROUND(AVERAGEIF('Top Ranked Jobs'!G7:G55,"Biotech",'Top Ranked Jobs'!L7:L55),1)
B11: Corporate FinTech | C11: =COUNTIF('Top Ranked Jobs'!G7:G55,"Corporate FinTech") | D11: {=MIN(IF('Top Ranked Jobs'!G7:G55="Corporate FinTech",'Top Ranked Jobs'!K7:K55))} | E11: {=MEDIAN(IF('Top Ranked Jobs'!G7:G55="Corporate FinTech",'Top Ranked Jobs'!K7:K55))} | F11: {=MAX(IF('Top Ranked Jobs'!G7:G55="Corporate FinTech",'Top Ranked Jobs'!K7:K55))} | G11: =ROUND(AVERAGEIF('Top Ranked Jobs'!G7:G55,"Corporate FinTech",'Top Ranked Jobs'!L7:L55),1)
B12: Medtech | C12: =COUNTIF('Top Ranked Jobs'!G7:G55,"Medtech") | D12: {=MIN(IF('Top Ranked Jobs'!G7:G55="Medtech",'Top Ranked Jobs'!K7:K55))} | E12: {=MEDIAN(IF('Top Ranked Jobs'!G7:G55="Medtech",'Top Ranked Jobs'!K7:K55))} | F12: {=MAX(IF('Top Ranked Jobs'!G7:G55="Medtech",'Top Ranked Jobs'!K7:K55))} | G12: =ROUND(AVERAGEIF('Top Ranked Jobs'!G7:G55,"Medtech",'Top Ranked Jobs'!L7:L55),1)
B13: Bank | C13: =COUNTIF('Top Ranked Jobs'!G7:G55,"Bank") | D13: {=MIN(IF('Top Ranked Jobs'!G7:G55="Bank",'Top Ranked Jobs'!K7:K55))} | E13: {=MEDIAN(IF('Top Ranked Jobs'!G7:G55="Bank",'Top Ranked Jobs'!K7:K55))} | F13: {=MAX(IF('Top Ranked Jobs'!G7:G55="Bank",'Top Ranked Jobs'!K7:K55))} | G13: =ROUND(AVERAGEIF('Top Ranked Jobs'!G7:G55,"Bank",'Top Ranked Jobs'!L7:L55),1)
B14: Mid-Market Consulting | C14: =COUNTIF('Top Ranked Jobs'!G7:G55,"Mid-Market Consulting") | D14: {=MIN(IF('Top Ranked Jobs'!G7:G55="Mid-Market Consulting",'Top Ranked Jobs'!K7:K55))} | E14: {=MEDIAN(IF('Top Ranked Jobs'!G7:G55="Mid-Market Consulting",'Top Ranked Jobs'!K7:K55))} | F14: {=MAX(IF('Top Ranked Jobs'!G7:G55="Mid-Market Consulting",'Top Ranked Jobs'!K7:K55))} | G14: =ROUND(AVERAGEIF('Top Ranked Jobs'!G7:G55,"Mid-Market Consulting",'Top Ranked Jobs'!L7:L55),1)
B15: G-SIB-Adj Bank | C15: =COUNTIF('Top Ranked Jobs'!G7:G55,"G-SIB-Adj Bank") | D15: {=MIN(IF('Top Ranked Jobs'!G7:G55="G-SIB-Adj Bank",'Top Ranked Jobs'!K7:K55))} | E15: {=MEDIAN(IF('Top Ranked Jobs'!G7:G55="G-SIB-Adj Bank",'Top Ranked Jobs'!K7:K55))} | F15: {=MAX(IF('Top Ranked Jobs'!G7:G55="G-SIB-Adj Bank",'Top Ranked Jobs'!K7:K55))} | G15: =ROUND(AVERAGEIF('Top Ranked Jobs'!G7:G55,"G-SIB-Adj Bank",'Top Ranked Jobs'!L7:L55),1)
B16: Energy | C16: =COUNTIF('Top Ranked Jobs'!G7:G55,"Energy") | D16: {=MIN(IF('Top Ranked Jobs'!G7:G55="Energy",'Top Ranked Jobs'!K7:K55))} | E16: {=MEDIAN(IF('Top Ranked Jobs'!G7:G55="Energy",'Top Ranked Jobs'!K7:K55))} | F16: {=MAX(IF('Top Ranked Jobs'!G7:G55="Energy",'Top Ranked Jobs'!K7:K55))} | G16: =ROUND(AVERAGEIF('Top Ranked Jobs'!G7:G55,"Energy",'Top Ranked Jobs'!L7:L55),1)
B17: Academic Admin | C17: =COUNTIF('Top Ranked Jobs'!G7:G55,"Academic Admin") | D17: {=MIN(IF('Top Ranked Jobs'!G7:G55="Academic Admin",'Top Ranked Jobs'!K7:K55))} | E17: {=MEDIAN(IF('Top Ranked Jobs'!G7:G55="Academic Admin",'Top Ranked Jobs'!K7:K55))} | F17: {=MAX(IF('Top Ranked Jobs'!G7:G55="Academic Admin",'Top Ranked Jobs'!K7:K55))} | G17: =ROUND(AVERAGEIF('Top Ranked Jobs'!G7:G55,"Academic Admin",'Top Ranked Jobs'!L7:L55),1)
B18: Community Bank | C18: =COUNTIF('Top Ranked Jobs'!G7:G55,"Community Bank") | D18: {=MIN(IF('Top Ranked Jobs'!G7:G55="Community Bank",'Top Ranked Jobs'!K7:K55))} | E18: {=MEDIAN(IF('Top Ranked Jobs'!G7:G55="Community Bank",'Top Ranked Jobs'!K7:K55))} | F18: {=MAX(IF('Top Ranked Jobs'!G7:G55="Community Bank",'Top Ranked Jobs'!K7:K55))} | G18: =ROUND(AVERAGEIF('Top Ranked Jobs'!G7:G55,"Community Bank",'Top Ranked Jobs'!L7:L55),1)
B19: Staffing | C19: =COUNTIF('Top Ranked Jobs'!G7:G55,"Staffing") | D19: {=MIN(IF('Top Ranked Jobs'!G7:G55="Staffing",'Top Ranked Jobs'!K7:K55))} | E19: {=MEDIAN(IF('Top Ranked Jobs'!G7:G55="Staffing",'Top Ranked Jobs'!K7:K55))} | F19: {=MAX(IF('Top Ranked Jobs'!G7:G55="Staffing",'Top Ranked Jobs'!K7:K55))} | G19: =ROUND(AVERAGEIF('Top Ranked Jobs'!G7:G55,"Staffing",'Top Ranked Jobs'!L7:L55),1)
B20: Academic-Adjunct | C20: =COUNTIF('Top Ranked Jobs'!G7:G55,"Academic-Adjunct") | D20: {=MIN(IF('Top Ranked Jobs'!G7:G55="Academic-Adjunct",'Top Ranked Jobs'!K7:K55))} | E20: {=MEDIAN(IF('Top Ranked Jobs'!G7:G55="Academic-Adjunct",'Top Ranked Jobs'!K7:K55))} | F20: {=MAX(IF('Top Ranked Jobs'!G7:G55="Academic-Adjunct",'Top Ranked Jobs'!K7:K55))} | G20: =ROUND(AVERAGEIF('Top Ranked Jobs'!G7:G55,"Academic-Adjunct",'Top Ranked Jobs'!L7:L55),1)

Sheet Tier Summary
B2: Tier Summary
B5: Tier | C5: Roles | D5: Min Sal Mid | E5: Median Sal Mid | F5: Max Sal Mid | G5: Avg Fit
B6: Tier 1 | C6: =COUNTIF('Top Ranked Jobs'!C7:C55,1) | D6: {=MIN(IF('Top Ranked Jobs'!C7:C55=1,'Top Ranked Jobs'!K7:K55))} | E6: {=MEDIAN(IF('Top Ranked Jobs'!C7:C55=1,'Top Ranked Jobs'!K7:K55))} | F6: {=MAX(IF('Top Ranked Jobs'!C7:C55=1,'Top Ranked Jobs'!K7:K55))} | G6: =ROUND(AVERAGEIF('Top Ranked Jobs'!C7:C55,1,'Top Ranked Jobs'!L7:L55),1)
B7: Tier 2 | C7: =COUNTIF('Top Ranked Jobs'!C7:C55,2) | D7: {=MIN(IF('Top Ranked Jobs'!C7:C55=2,'Top Ranked Jobs'!K7:K55))} | E7: {=MEDIAN(IF('Top Ranked Jobs'!C7:C55=2,'Top Ranked Jobs'!K7:K55))} | F7: {=MAX(IF('Top Ranked Jobs'!C7:C55=2,'Top Ranked Jobs'!K7:K55))} | G7: =ROUND(AVERAGEIF('Top Ranked Jobs'!C7:C55,2,'Top Ranked Jobs'!L7:L55),1)
B8: Tier 3 | C8: =COUNTIF('Top Ranked Jobs'!C7:C55,3) | D8: {=MIN(IF('Top Ranked Jobs'!C7:C55=3,'Top Ranked Jobs'!K7:K55))} | E8: {=MEDIAN(IF('Top Ranked Jobs'!C7:C55=3,'Top Ranked Jobs'!K7:K55))} | F8: {=MAX(IF('Top Ranked Jobs'!C7:C55=3,'Top Ranked Jobs'!K7:K55))} | G8: =ROUND(AVERAGEIF('Top Ranked Jobs'!C7:C55,3,'Top Ranked Jobs'!L7:L55),1)
B9: Tier 4 | C9: =COUNTIF('Top Ranked Jobs'!C7:C55,4) | D9: {=MIN(IF('Top Ranked Jobs'!C7:C55=4,'Top Ranked Jobs'!K7:K55))} | E9: {=MEDIAN(IF('Top Ranked Jobs'!C7:C55=4,'Top Ranked Jobs'!K7:K55))} | F9: {=MAX(IF('Top Ranked Jobs'!C7:C55=4,'Top Ranked Jobs'!K7:K55))} | G9: =ROUND(AVERAGEIF('Top Ranked Jobs'!C7:C55,4,'Top Ranked Jobs'!L7:L55),1)
B10: OVERALL | C10: =COUNTA('Top Ranked Jobs'!D7:D55) | D10: =MIN('Top Ranked Jobs'!K7:K55) | E10: =MEDIAN('Top Ranked Jobs'!K7:K55) | F10: =MAX('Top Ranked Jobs'!K7:K55) | G10: =ROUND(AVERAGE('Top Ranked Jobs'!L7:L55),1)

Sheet Action Plan
B2: Four-Week Application Plan
B5: Week | C5: Window | D5: Company | E5: Title | F5: Tier | G5: Fit | H5: Suggested move
B6: Week 1 | C6: May 18 – May 22 | D6: JPMorgan Chase | E6: Executive Director, AI/ML Audit | F6: 1 | G6: 9.5 | H6: Tailored resume + cover letter this week. Reach out to one internal referrer.
B7: Week 1 | C7: May 18 – May 22 | D7: BNY | E7: Managing Director, AI Governance Audit | F7: 1 | G7: 9.2 | H7: Tailored resume + cover letter this week. Reach out to one internal referrer.
B8: Week 1 | C8: May 18 – May 22 | D8: Bristol Myers Squibb | E8: Executive Director, Internal Audit | F8: 1 | G8: 9.4 | H8: Tailored resume + cover letter this week. Reach out to one internal referrer.
B9: Week 1 | C9: May 18 – May 22 | D9: Morgan Stanley | E9: Executive Director, Technology & AI Audit | F9: 1 | G9: 9 | H9: Tailored resume + cover letter this week. Reach out to one internal referrer.
B10: Week 1 | C10: May 18 – May 22 | D10: Goldman Sachs | E10: VP, AI Governance & Model Risk Audit | F10: 1 | G10: 9 | H10: Tailored resume + cover letter this week. Reach out to one internal referrer.
B11: Week 1 | C11: May 18 – May 22 | D11: Prudential Financial | E11: VP, Internal Audit — AI & Model Risk | F11: 1 | G11: 9.6 | H11: Tailored resume + cover letter this week. Reach out to one internal referrer.
B12: Week 1 | C12: May 18 – May 22 | D12: Johnson & Johnson | E12: Senior Director, Internal Audit — AI & Digital | F12: 1 | G12: 9.2 | H12: Tailored resume + cover letter this week. Reach out to one internal referrer.
B13: Week 1 | C13: May 18 – May 22 | D13: Citi | E13: Director, AI Audit (return engagement) | F13: 1 | G13: 9 | H13: Tailored resume + cover letter this week. Reach out to one internal referrer.
B14: Week 1 | C14: May 18 – May 22 | D14: Merck | E14: Director, Internal Audit — Technology & AI | F14: 1 | G14: 9.1 | H14: Tailored resume + cover letter this week. Reach out to one internal referrer.
B15: Week 2 | C15: May 25 – May 29 | D15: Wells Fargo | E15: SVP, AI Risk Oversight (3LOD audit) | F15: 2 | G15: 8.4 | H15: Apply via stable career portal. Note referral targets on LinkedIn.
B16: Week 2 | C16: May 25 – May 29 | D16: PwC | E16: Director, Risk Assurance — AI & Model Risk | F16: 2 | G16: 8.3 | H16: Apply via stable career portal. Note referral targets on LinkedIn.
B17: Week 2 | C17: May 25 – May 29 | D17: BioNTech US | E17: Senior Director, Internal Audit | F17: 2 | G17: 8 | H17: Apply via stable career portal. Note referral targets on LinkedIn.
... B49: Week 4 | C49: Jun 08 – Jun 12 | D49: Essex County College | E49: Adjunct Faculty — Business Management | F49: 4 | G49: 5.5 | H49: Adjunct apps — submit via PeopleAdmin. Stack teaching credential while search runs.
